<testsuite>
  <testsuites name="./gradlew runFix" tests="1">
    <testcase name="[:throwExceptionWithSuggestedFix] error: ExceptionWithSuggestedFixMessage" className="[:throwExceptionWithSuggestedFix] error: ExceptionWithSuggestedFixMessage" time="0">
      <failure message="_IGNORED_IN_TESTS" type="ERROR">ExceptionWithSuggestedFixMessage

* Causal chain is:
	org.gradle.api.tasks.TaskExecutionException: Execution failed for task ':throwExceptionWithSuggestedFix'.
	com.palantir.gradle.failurereports.exceptions.ExceptionWithSuggestion: ExceptionWithSuggestedFixMessage

* Full exception is:
org.gradle.api.tasks.TaskExecutionException: Execution failed for task ':throwExceptionWithSuggestedFix'.
Caused by: com.palantir.gradle.failurereports.exceptions.ExceptionWithSuggestion: ExceptionWithSuggestedFixMessage


This failure report is produced by the `com.palantir.failure-reports plugin`, which retrieves information from the exceptions generated by failed tasks. For further details about the failure, refer to the stdout logs. Due to a known issue (https://github.com/gradle/gradle/issues/6068), error logs for a generic task are not included in the report.
Please report any issues and share your feedback at https://github.com/palantir/gradle-failure-reports/issues.</failure>
    </testcase>
  </testsuites>
  <testsuites name="./gradlew fixMe" tests="1">
    <testcase name="[:myProject:throwInnerExceptionWithSuggestedFix] error: InnerExceptionWithSuggestedFixMessage" className="[:myProject:throwInnerExceptionWithSuggestedFix] error: InnerExceptionWithSuggestedFixMessage" time="0">
      <failure message="_IGNORED_IN_TESTS" type="ERROR">InnerExceptionWithSuggestedFixMessage

* Causal chain is:
	org.gradle.api.tasks.TaskExecutionException: Execution failed for task ':myProject:throwInnerExceptionWithSuggestedFix'.
	org.gradle.api.GradleException: OuterGradleException
	com.palantir.gradle.failurereports.exceptions.ExceptionWithSuggestion: InnerExceptionWithSuggestedFixMessage
	java.lang.RuntimeException: InnerRuntimeException

* Full exception is:
org.gradle.api.tasks.TaskExecutionException: Execution failed for task ':myProject:throwInnerExceptionWithSuggestedFix'.
Caused by: org.gradle.api.GradleException: OuterGradleException
Caused by: com.palantir.gradle.failurereports.exceptions.ExceptionWithSuggestion: InnerExceptionWithSuggestedFixMessage
	... PLACEHOLDER_NUMBER more
Caused by: java.lang.RuntimeException: InnerRuntimeException
	... PLACEHOLDER_NUMBER more


This failure report is produced by the `com.palantir.failure-reports plugin`, which retrieves information from the exceptions generated by failed tasks. For further details about the failure, refer to the stdout logs. Due to a known issue (https://github.com/gradle/gradle/issues/6068), error logs for a generic task are not included in the report.
Please report any issues and share your feedback at https://github.com/palantir/gradle-failure-reports/issues.</failure>
    </testcase>
  </testsuites>
  <testsuites name=":myProject:throwGradleException" tests="1">
    <testcase name="[:myProject:throwGradleException] error: Execution failed for task ':myProject:throwGradleException'." className="[:myProject:throwGradleException] error: Execution failed for task ':myProject:throwGradleException'." time="0">
      <failure message="_IGNORED_IN_TESTS" type="ERROR">This is a gradle exception that is not ignored

* Causal chain is:
	org.gradle.api.tasks.TaskExecutionException: Execution failed for task ':myProject:throwGradleException'.
	org.gradle.api.GradleException: This is a gradle exception that is not ignored

* Full exception is:
org.gradle.api.tasks.TaskExecutionException: Execution failed for task ':myProject:throwGradleException'.
Caused by: org.gradle.api.GradleException: This is a gradle exception that is not ignored


This failure report is produced by the `com.palantir.failure-reports plugin`, which retrieves information from the exceptions generated by failed tasks. For further details about the failure, refer to the stdout logs. Due to a known issue (https://github.com/gradle/gradle/issues/6068), error logs for a generic task are not included in the report.
Please report any issues and share your feedback at https://github.com/palantir/gradle-failure-reports/issues.</failure>
    </testcase>
  </testsuites>
  <testsuites name=":myProject:throwOOM" tests="1">
    <testcase name="[:myProject:throwOOM] error: Execution failed for task ':myProject:throwOOM'." className="[:myProject:throwOOM] error: Execution failed for task ':myProject:throwOOM'." time="0">
      <failure message="_IGNORED_IN_TESTS" type="ERROR">An error occurred, java.lang.OutOfMemoryError exception thrown

* Causal chain is:
	org.gradle.api.tasks.TaskExecutionException: Execution failed for task ':myProject:throwOOM'.
	java.lang.OutOfMemoryError

* Full exception is:
org.gradle.api.tasks.TaskExecutionException: Execution failed for task ':myProject:throwOOM'.
Caused by: java.lang.OutOfMemoryError


This failure report is produced by the `com.palantir.failure-reports plugin`, which retrieves information from the exceptions generated by failed tasks. For further details about the failure, refer to the stdout logs. Due to a known issue (https://github.com/gradle/gradle/issues/6068), error logs for a generic task are not included in the report.
Please report any issues and share your feedback at https://github.com/palantir/gradle-failure-reports/issues.</failure>
    </testcase>
  </testsuites>
</testsuite>
